<?xml version="1.0" encoding="utf-8"?>
<!-- This URDF was automatically created by SolidWorks to URDF Exporter! Originally created by Stephen Brawner (brawner@gmail.com) 
     Commit Version: 1.5.1-0-g916b5db  Build Version: 1.5.7152.31018
     For more information, please see http://wiki.ros.org/sw_urdf_exporter -->
<robot
  name="my_robot.SLDASM">
  <link
    name="base_link">
    <inertial>
      <origin
        xyz="2.66795449371288E-17 0.0387396668216388 -0.00271259423342531"
        rpy="0 0 0" />
      <mass
        value="2.08066334572316" />
      <inertia
        ixx="0.0111893446770807"
        ixy="-2.09958341107228E-19"
        ixz="-8.38375274563171E-18"
        iyy="0.0111893446770807"
        iyz="4.88900452786412E-19"
        izz="0.0185863687856069" />
    </inertial>
    <visual>
      <origin
        xyz="0 0 0"
        rpy="0 0 0" />
      <geometry>
        <mesh
          filename="package://my_robot.SLDASM/meshes/base_link.STL" />
      </geometry>
      <material
        name="">
        <color
          rgba="0.294117647058824 0.294117647058824 0.294117647058824 1" />
      </material>
    </visual>
    <collision>
      <origin
        xyz="0 0 0"
        rpy="0 0 0" />
      <geometry>
        <mesh
          filename="package://my_robot.SLDASM/meshes/base_link.STL" />
      </geometry>
    </collision>
  </link>
  <link
    name="left_front">
    <inertial>
      <origin
        xyz="0 0 -0.0526463983977137"
        rpy="0 0 0" />
      <mass
        value="0.520165836430788" />
      <inertia
        ixx="0.00279733616927018"
        ixy="-1.35525271560688E-20"
        ixz="7.41513776015714E-18"
        iyy="0.00279733616927018"
        iyz="1.10224102510803E-20"
        izz="0.00464659219640172" />
    </inertial>
    <visual>
      <origin
        xyz="0 0 0"
        rpy="0 0 0" />
      <geometry>
        <mesh
          filename="package://my_robot.SLDASM/meshes/left_front.STL" />
      </geometry>
      <material
        name="">
        <color
          rgba="0.294117647058824 0.294117647058824 0.294117647058824 1" />
      </material>
    </visual>
    <collision>
      <origin
        xyz="0 0 0"
        rpy="0 0 0" />
      <geometry>
        <mesh
          filename="package://my_robot.SLDASM/meshes/left_front.STL" />
      </geometry>
    </collision>
  </link>
  <joint
    name="j1"
    type="continuous">
    <origin
      xyz="-0.175 -0.16964 0.03874"
      rpy="-1.5708 -0.0061645 0" />
    <parent
      link="base_link" />
    <child
      link="left_front" />
    <axis
      xyz="0 0 1" />
  </joint>
  <link
    name="left_back">
    <inertial>
      <origin
        xyz="-2.77555756156289E-17 0 -0.052646398397714"
        rpy="0 0 0" />
      <mass
        value="0.520165836430789" />
      <inertia
        ixx="0.00279733616927018"
        ixy="-2.62400836799755E-35"
        ixz="2.14236638453903E-19"
        iyy="0.00279733616927018"
        iyz="8.64860785067882E-35"
        izz="0.00464659219640172" />
    </inertial>
    <visual>
      <origin
        xyz="0 0 0"
        rpy="0 0 0" />
      <geometry>
        <mesh
          filename="package://my_robot.SLDASM/meshes/left_back.STL" />
      </geometry>
      <material
        name="">
        <color
          rgba="0.294117647058824 0.294117647058824 0.294117647058824 1" />
      </material>
    </visual>
    <collision>
      <origin
        xyz="0 0 0"
        rpy="0 0 0" />
      <geometry>
        <mesh
          filename="package://my_robot.SLDASM/meshes/left_back.STL" />
      </geometry>
    </collision>
  </link>
  <joint
    name="j2"
    type="continuous">
    <origin
      xyz="0.175 -0.16964 0.03874"
      rpy="-1.5708 0 0" />
    <parent
      link="base_link" />
    <child
      link="left_back" />
    <axis
      xyz="0 0 1" />
  </joint>
  <link
    name="right_front">
    <inertial>
      <origin
        xyz="-1.38777878078145E-17 0 0.0527125942334249"
        rpy="0 0 0" />
      <mass
        value="0.52016583643079" />
      <inertia
        ixx="0.00279733616927019"
        ixy="1.0842021724855E-19"
        ixz="2.71171038075666E-19"
        iyy="0.00279733616927019"
        iyz="7.1100201075559E-19"
        izz="0.00464659219640172" />
    </inertial>
    <visual>
      <origin
        xyz="0 0 0"
        rpy="0 0 0" />
      <geometry>
        <mesh
          filename="package://my_robot.SLDASM/meshes/right_front.STL" />
      </geometry>
      <material
        name="">
        <color
          rgba="0.294117647058824 0.294117647058824 0.294117647058824 1" />
      </material>
    </visual>
    <collision>
      <origin
        xyz="0 0 0"
        rpy="0 0 0" />
      <geometry>
        <mesh
          filename="package://my_robot.SLDASM/meshes/right_front.STL" />
      </geometry>
    </collision>
  </link>
  <joint
    name="j3"
    type="continuous">
    <origin
      xyz="-0.175 0.175 0.03874"
      rpy="-1.5708 1.1763 0" />
    <parent
      link="base_link" />
    <child
      link="right_front" />
    <axis
      xyz="0 0 1" />
  </joint>
  <link
    name="right_back">
    <inertial>
      <origin
        xyz="-2.77555756156289E-17 0 0.052712594233425"
        rpy="0 0 0" />
      <mass
        value="0.52016583643079" />
      <inertia
        ixx="0.00279733616927019"
        ixy="-4.08409110643696E-35"
        ixz="1.30664019882332E-18"
        iyy="0.00279733616927019"
        iyz="-8.66689941233715E-34"
        izz="0.00464659219640172" />
    </inertial>
    <visual>
      <origin
        xyz="0 0 0"
        rpy="0 0 0" />
      <geometry>
        <mesh
          filename="package://my_robot.SLDASM/meshes/right_back.STL" />
      </geometry>
      <material
        name="">
        <color
          rgba="0.294117647058824 0.294117647058824 0.294117647058824 1" />
      </material>
    </visual>
    <collision>
      <origin
        xyz="0 0 0"
        rpy="0 0 0" />
      <geometry>
        <mesh
          filename="package://my_robot.SLDASM/meshes/right_back.STL" />
      </geometry>
    </collision>
  </link>
  <joint
    name="j4"
    type="continuous">
    <origin
      xyz="0.175 0.175 0.03874"
      rpy="-1.5708 0 0" />
    <parent
      link="base_link" />
    <child
      link="right_back" />
    <axis
      xyz="0 0 1" />
  </joint>
</robot>